Workbook

Sheet Portada
A1: TAREA COMPUTACIONAL 1 - OPTIMIZACIÓN
A2: Universidad Diego Portales | Escuela de Ingeniería Industrial
A4: Integrantes del grupo:
A5: 1. [Nombre completo] — [correo institucional]
A6: 2. [Nombre completo] — [correo institucional]
A7: 3. [Nombre completo] — [correo institucional]
A8: 4. [Nombre completo] — [correo institucional]
A9: 5. [Nombre completo] — [correo institucional]
A11: Instrucciones de uso de este archivo:
A12: 1. Este libro contiene el modelo YA FORMULADO con fórmulas reales (no valores pegados), listo para resolver con Solver.
A13: 2. Celdas AZULES sobre fondo blanco = parámetros/datos fijos de la pauta (no tocar).
A14: 3. Celdas AZULES con fondo celeste = variables de decisión / celdas cambiantes de Solver (parten en 0).
... A21: 8. Reemplaza los nombres de los integrantes del grupo arriba antes de entregar.

Sheet Parte 1 - Modelo Base
A1: TAREA COMPUTACIONAL 1 - OPTIMIZACIÓN | Parte 1: Modelo Productivo Base
A3: 1. PARÁMETROS (celdas azules = datos fijos de la pauta)
B4: Mes 1 | C4: Mes 2 | D4: Mes 3 | E4: Mes 4 | F4: Mes 5 | G4: Mes 6 | H4: Mes 7 | I4: Mes 8 | J4: Mes 9 | K4: Mes 10 | L4: Mes 11 | M4: Mes 12 | N4: Total
A5: Demanda Máxima A (unid) | B5: 73 | C5: 60 | D5: 48 | E5: 66 | F5: 63 | G5: 48 | H5: 57 | I5: 68 | J5: 52 | K5: 76 | L5: 67 | M5: 76
A6: Demanda Máxima B (unid) | B6: 63 | C6: 72 | D6: 57 | E6: 67 | F6: 44 | G6: 59 | H6: 48 | I6: 64 | J6: 40 | K6: 63 | L6: 64 | M6: 77
A7: Utilidad Venta A ($/unid) | B7: 8 | C7: 22 | D7: 6 | E7: 32 | F7: 28 | G7: 14 | H7: 20 | I7: 36 | J7: 10 | K7: 6 | L7: 40 | M7: 22
A8: Utilidad Venta B ($/unid) | B8: 20 | C8: 16 | D8: 20 | E8: 6 | F8: 20 | G8: 29 | H8: 8 | I8: 30 | J8: 6 | K8: 8 | L8: 6 | M8: 28
A9: Horas Máquina A (hr/unid) | B9: 0.1 | C9: 2 | D9: 0.9 | E9: 1.2 | F9: 1.8 | G9: 0.7 | H9: 0.8 | I9: 0.4 | J9: 1.5 | K9: 2.1 | L9: 1.9 | M9: 1.5
A10: Horas Máquina B (hr/unid) | B10: 0.2 | C10: 1.9 | D10: 0.7 | E10: 1.7 | F10: 0.8 | G10: 1.6 | H10: 1 | I10: 0.6 | J10: 1.5 | K10: 0.3 | L10: 2 | M10: 1.4
A11: Capacidad Maquinaria (hr) | B11: 180 | C11: 180 | D11: 160 | E11: 190 | F11: 130 | G11: 160 | H11: 160 | I11: 130 | J11: 140 | K11: 150 | L11: 150 | M11: 150
A12: Costo Inventario ($/unid) | B12: 3 | C12: 5 | D12: 2 | E12: 4 | F12: 2 | G12: 4 | H12: 2 | I12: 6 | J12: 2 | K12: 2 | L12: 4 | M12: 2
A13: Inventario Seguridad (unid) | B13: 6 | C13: 7 | D13: 10 | E13: 5 | F13: 10 | G13: 7 | H13: 7 | I13: 10 | J13: 5 | K13: 7 | L13: 9 | M13: 8
A14: Inventario Máximo Bodega (unid) | B14: 30 | C14: 30 | D14: 27 | E14: 24 | F14: 25 | G14: 21 | H14: 21 | I14: 25 | J14: 22 | K14: 25 | L14: 22 | M14: 30
A16: Inventario Inicial A (t=0, unid) | B16: 10
A17: Inventario Inicial B (t=0, unid) | B17: 10
A19: 2. VARIABLES DE DECISIÓN — CELDAS CAMBIANTES PARA SOLVER (celda azul y fondo celeste)
B20: Mes 1 | C20: Mes 2 | D20: Mes 3 | E20: Mes 4 | F20: Mes 5 | G20: Mes 6 | H20: Mes 7 | I20: Mes 8 | J20: Mes 9 | K20: Mes 10 | L20: Mes 11 | M20: Mes 12 | N20: Total
A21: Producción A (X_A,t) | B21: 0 | C21: 0 | D21: 0 | E21: 0 | F21: 0 | G21: 0 | H21: 0 | I21: 0 | J21: 0 | K21: 0 | L21: 0 | M21: 0 | N21: =SUM(B21:M21) -> 0
A22: Producción B (X_B,t) | B22: 0 | C22: 0 | D22: 0 | E22: 0 | F22: 0 | G22: 0 | H22: 0 | I22: 0 | J22: 0 | K22: 0 | L22: 0 | M22: 0 | N22: =SUM(B22:M22) -> 0
A23: Ventas A (V_A,t) | B23: 0 | C23: 0 | D23: 0 | E23: 0 | F23: 0 | G23: 0 | H23: 0 | I23: 0 | J23: 0 | K23: 0 | L23: 0 | M23: 0 | N23: =SUM(B23:M23) -> 0
A24: Ventas B (V_B,t) | B24: 0 | C24: 0 | D24: 0 | E24: 0 | F24: 0 | G24: 0 | H24: 0 | I24: 0 | J24: 0 | K24: 0 | L24: 0 | M24: 0 | N24: =SUM(B24:M24) -> 0
A26: 3. VARIABLES CALCULADAS (fórmulas — NO son celdas cambiantes)
B27: Mes 1 | C27: Mes 2 | D27: Mes 3 | E27: Mes 4 | F27: Mes 5 | G27: Mes 6 | H27: Mes 7 | I27: Mes 8 | J27: Mes 9 | K27: Mes 10 | L27: Mes 11 | M27: Mes 12 | N27: Total
A28: Inventario Final A (I_A,t) | B28: =$B$16+B21-B23 -> 10 | C28: =B28+C21-C23 -> 10 | D28: =C28+D21-D23 -> 10 | E28: =D28+E21-E23 -> 10 | F28: =E28+F21-F23 -> 10 | G28: =F28+G21-G23 -> 10 | H28: =G28+H21-H23 -> 10 | I28: =H28+I21-I23 -> 10 | J28: =I28+J21-J23 -> 10 | ... M28: =L28+M21-M23 -> 10 | N28: —
A29: Inventario Final B (I_B,t) | B29: =$B$17+B22-B24 -> 10 | C29: =B29+C22-C24 -> 10 | D29: =C29+D22-D24 -> 10 | E29: =D29+E22-E24 -> 10 | F29: =E29+F22-F24 -> 10 | G29: =F29+G22-G24 -> 10 | H29: =G29+H22-H24 -> 10 | I29: =H29+I22-I24 -> 10 | J29: =I29+J22-J24 -> 10 | ... M29: =L29+M22-M24 -> 10 | N29: —
A30: Inventario Total en Bodega (I_A+I_B) | B30: =B28+B29 -> 20 | C30: =C28+C29 -> 20 | D30: =D28+D29 -> 20 | E30: =E28+E29 -> 20 | F30: =F28+F29 -> 20 | G30: =G28+G29 -> 20 | H30: =H28+H29 -> 20 | I30: =I28+I29 -> 20 | ... M30: =M28+M29 -> 20 | N30: —
A31: Horas Máquina Usadas (hr) | B31: =B9*B21+B10*B22 -> 0 | C31: =C9*C21+C10*C22 -> 0 | D31: =D9*D21+D10*D22 -> 0 | E31: =E9*E21+E10*E22 -> 0 | F31: =F9*F21+F10*F22 -> 0 | G31: =G9*G21+G10*G22 -> 0 | H31: =H9*H21+H10*H22 -> 0 | I31: =I9*I21+I10*I22 -> 0 | ... M31: =M9*M21+M10*M22 -> 0 | N31: =SUM(B31:M31) -> 0
A32: Holgura Maquinaria (Cap. - Usadas) | B32: =B11-B31 -> 180 | C32: =C11-C31 -> 180 | D32: =D11-D31 -> 160 | E32: =E11-E31 -> 190 | F32: =F11-F31 -> 130 | G32: =G11-G31 -> 160 | H32: =H11-H31 -> 160 | I32: =I11-I31 -> 130 | ... M32: =M11-M31 -> 150 | N32: —
A34: 4. FUNCIÓN OBJETIVO Y RESULTADOS FINANCIEROS
A35: Ingresos Totales por Ventas ($) | B35: =SUMPRODUCT(B7:M7,B23:M23)+SUMPRODUCT(B8:M8,B24:M24) -> 0
A36: Costo Total de Inventario ($) | B36: =SUMPRODUCT(B12:M12,B30:M30) -> 760
A37: BENEFICIO NETO ANUAL ($) <<< CELDA OBJETIVO SOLVER >>> | B37: =B35-B36 -> -760
A39: 5. CONFIGURACIÓN DE SOLVER (Datos > Solver)
A40: • Establecer el objetivo (Set Objective): $B$37 → Máx
A41: • Cambiando las celdas de variables (By Changing Variable Cells):
A42: $B$21:$M$21, $B$22:$M$22, $B$23:$M$23, $B$24:$M$24
A43: • Restricciones (Add):
A44: $B$23:$M$23 <= $B$5:$M$5 (no vender más que la demanda A)
A45: $B$24:$M$24 <= $B$6:$M$6 (no vender más que la demanda B)
A46: $B$31:$M$31 <= $B$11:$M$11 (capacidad de maquinaria)
...

Sheet Parte 2 - Con RRHH
A1: TAREA COMPUTACIONAL 1 - OPTIMIZACIÓN | Parte 2: Modelo Integrado con Recursos Humanos
A3: 1. PARÁMETROS (celdas azules = datos fijos de la pauta)
B4: Mes 1 | C4: Mes 2 | D4: Mes 3 | E4: Mes 4 | F4: Mes 5 | G4: Mes 6 | H4: Mes 7 | I4: Mes 8 | J4: Mes 9 | K4: Mes 10 | L4: Mes 11 | M4: Mes 12 | N4: Total
A5: Demanda Máxima A (unid) | B5: 73 | C5: 60 | D5: 48 | E5: 66 | F5: 63 | G5: 48 | H5: 57 | I5: 68 | J5: 52 | K5: 76 | L5: 67 | M5: 76
A6: Demanda Máxima B (unid) | B6: 63 | C6: 72 | D6: 57 | E6: 67 | F6: 44 | G6: 59 | H6: 48 | I6: 64 | J6: 40 | K6: 63 | L6: 64 | M6: 77
A7: Utilidad Venta A ($/unid) | B7: 8 | C7: 22 | D7: 6 | E7: 32 | F7: 28 | G7: 14 | H7: 20 | I7: 36 | J7: 10 | K7: 6 | L7: 40 | M7: 22
A8: Utilidad Venta B ($/unid) | B8: 20 | C8: 16 | D8: 20 | E8: 6 | F8: 20 | G8: 29 | H8: 8 | I8: 30 | J8: 6 | K8: 8 | L8: 6 | M8: 28
A9: Horas Máquina A (hr/unid) | B9: 0.1 | C9: 2 | D9: 0.9 | E9: 1.2 | F9: 1.8 | G9: 0.7 | H9: 0.8 | I9: 0.4 | J9: 1.5 | K9: 2.1 | L9: 1.9 | M9: 1.5
A10: Horas Máquina B (hr/unid) | B10: 0.2 | C10: 1.9 | D10: 0.7 | E10: 1.7 | F10: 0.8 | G10: 1.6 | H10: 1 | I10: 0.6 | J10: 1.5 | K10: 0.3 | L10: 2 | M10: 1.4
A11: Capacidad Maquinaria (hr) | B11: 180 | C11: 180 | D11: 160 | E11: 190 | F11: 130 | G11: 160 | H11: 160 | I11: 130 | J11: 140 | K11: 150 | L11: 150 | M11: 150
A12: Costo Inventario ($/unid) | B12: 3 | C12: 5 | D12: 2 | E12: 4 | F12: 2 | G12: 4 | H12: 2 | I12: 6 | J12: 2 | K12: 2 | L12: 4 | M12: 2
A13: Inventario Seguridad (unid) | B13: 6 | C13: 7 | D13: 10 | E13: 5 | F13: 10 | G13: 7 | H13: 7 | I13: 10 | J13: 5 | K13: 7 | L13: 9 | M13: 8
A14: Inventario Máximo Bodega (unid) | B14: 30 | C14: 30 | D14: 27 | E14: 24 | F14: 25 | G14: 21 | H14: 21 | I14: 25 | J14: 22 | K14: 25 | L14: 22 | M14: 30
A15: Costo Horario Regular ($/hh) | B15: 2.8 | C15: 0.6 | D15: 2.8 | E15: 1 | F15: 2.5 | G15: 0.8 | H15: 1.4 | I15: 1.5 | J15: 3.6 | K15: 3.2 | L15: 4.2 | M15: 2.6
A16: Costo Horas Extras ($/hh) | B16: 3.4 | C16: 0.9 | D16: 3.4 | E16: 2 | F16: 3.2 | G16: 1.3 | H16: 2.5 | I16: 2.2 | J16: 4 | K16: 4.1 | L16: 5.2 | M16: 3.7
... A18: Costo Despido ($/hh) | B18: 2 | C18: 1 | D18: 1 | E18: 1 | F18: 1 | G18: 0.5 | H18: 0.5 | I18: 0.5 | J18: 1 | K18: 1 | L18: 1 | M18: 1
A20: Inventario Inicial A (t=0, unid) | B20: 10
A21: Inventario Inicial B (t=0, unid) | B21: 10
A22: Dotación Inicial de Fuerza Laboral (hh, t=0) | B22: 300
A23: Requerimiento Mano de Obra (hh/unidad producida) | B23: 3
A25: 2. VARIABLES DE DECISIÓN — CELDAS CAMBIANTES PARA SOLVER (celda azul y fondo celeste)
B26: Mes 1 | C26: Mes 2 | D26: Mes 3 | E26: Mes 4 | F26: Mes 5 | G26: Mes 6 | H26: Mes 7 | I26: Mes 8 | J26: Mes 9 | K26: Mes 10 | L26: Mes 11 | M26: Mes 12 | N26: Total
A27: Producción A (X_A,t) | B27: 0 | C27: 0 | D27: 0 | E27: 0 | F27: 0 | G27: 0 | H27: 0 | I27: 0 | J27: 0 | K27: 0 | L27: 0 | M27: 0 | N27: =SUM(B27:M27) -> 0
A28: Producción B (X_B,t) | B28: 0 | C28: 0 | D28: 0 | E28: 0 | F28: 0 | G28: 0 | H28: 0 | I28: 0 | J28: 0 | K28: 0 | L28: 0 | M28: 0 | N28: =SUM(B28:M28) -> 0
A29: Ventas A (V_A,t) | B29: 0 | C29: 0 | D29: 0 | E29: 0 | F29: 0 | G29: 0 | H29: 0 | I29: 0 | J29: 0 | K29: 0 | L29: 0 | M29: 0 | N29: =SUM(B29:M29) -> 0
A30: Ventas B (V_B,t) | B30: 0 | C30: 0 | D30: 0 | E30: 0 | F30: 0 | G30: 0 | H30: 0 | I30: 0 | J30: 0 | K30: 0 | L30: 0 | M30: 0 | N30: =SUM(B30:M30) -> 0
A31: Horas Contratadas (H_t) | B31: 0 | C31: 0 | D31: 0 | E31: 0 | F31: 0 | G31: 0 | H31: 0 | I31: 0 | J31: 0 | K31: 0 | L31: 0 | M31: 0 | N31: =SUM(B31:M31) -> 0
A32: Horas Despedidas (F_t) | B32: 0 | C32: 0 | D32: 0 | E32: 0 | F32: 0 | G32: 0 | H32: 0 | I32: 0 | J32: 0 | K32: 0 | L32: 0 | M32: 0 | N32: =SUM(B32:M32) -> 0
A33: Horas Extras Utilizadas (O_t) | B33: 0 | C33: 0 | D33: 0 | E33: 0 | F33: 0 | G33: 0 | H33: 0 | I33: 0 | J33: 0 | K33: 0 | L33: 0 | M33: 0 | N33: =SUM(B33:M33) -> 0
A35: 3. VARIABLES CALCULADAS (fórmulas — NO son celdas cambiantes)
B36: Mes 1 | C36: Mes 2 | D36: Mes 3 | E36: Mes 4 | F36: Mes 5 | G36: Mes 6 | H36: Mes 7 | I36: Mes 8 | J36: Mes 9 | K36: Mes 10 | L36: Mes 11 | M36: Mes 12 | N36: Total
A37: Inventario Final A (I_A,t) | B37: =$B$20+B27-B29 -> 10 | C37: =B37+C27-C29 -> 10 | D37: =C37+D27-D29 -> 10 | E37: =D37+E27-E29 -> 10 | F37: =E37+F27-F29 -> 10 | G37: =F37+G27-G29 -> 10 | H37: =G37+H27-H29 -> 10 | I37: =H37+I27-I29 -> 10 | J37: =I37+J27-J29 -> 10 | ... M37: =L37+M27-M29 -> 10 | N37: —
A38: Inventario Final B (I_B,t) | B38: =$B$21+B28-B30 -> 10 | C38: =B38+C28-C30 -> 10 | D38: =C38+D28-D30 -> 10 | E38: =D38+E28-E30 -> 10 | F38: =E38+F28-F30 -> 10 | G38: =F38+G28-G30 -> 10 | H38: =G38+H28-H30 -> 10 | I38: =H38+I28-I30 -> 10 | J38: =I38+J28-J30 -> 10 | ... M38: =L38+M28-M30 -> 10 | N38: —
A39: Inventario Total en Bodega (I_A+I_B) | B39: =B37+B38 -> 20 | C39: =C37+C38 -> 20 | D39: =D37+D38 -> 20 | E39: =E37+E38 -> 20 | F39: =F37+F38 -> 20 | G39: =G37+G38 -> 20 | H39: =H37+H38 -> 20 | I39: =I37+I38 -> 20 | ... M39: =M37+M38 -> 20 | N39: —
A40: Dotación Disponible (W_t, hh) | B40: =$B$22+B31-B32 -> 300 | C40: =B40+C31-C32 -> 300 | D40: =C40+D31-D32 -> 300 | E40: =D40+E31-E32 -> 300 | F40: =E40+F31-F32 -> 300 | G40: =F40+G31-G32 -> 300 | H40: =G40+H31-H32 -> 300 | I40: =H40+I31-I32 -> 300 | J40: =I40+J31-J32 -> 300 | ... M40: =L40+M31-M32 -> 300 | N40: —
A41: Horas Máquina Usadas (hr) | B41: =B9*B27+B10*B28 -> 0 | C41: =C9*C27+C10*C28 -> 0 | D41: =D9*D27+D10*D28 -> 0 | E41: =E9*E27+E10*E28 -> 0 | F41: =F9*F27+F10*F28 -> 0 | G41: =G9*G27+G10*G28 -> 0 | H41: =H9*H27+H10*H28 -> 0 | I41: =I9*I27+I10*I28 -> 0 | ... M41: =M9*M27+M10*M28 -> 0 | N41: =SUM(B41:M41) -> 0
A42: Holgura Maquinaria (Cap. - Usadas) | B42: =B11-B41 -> 180 | C42: =C11-C41 -> 180 | D42: =D11-D41 -> 160 | E42: =E11-E41 -> 190 | F42: =F11-F41 -> 130 | G42: =G11-G41 -> 160 | H42: =H11-H41 -> 160 | I42: =I11-I41 -> 130 | ... M42: =M11-M41 -> 150 | N42: —
A43: Requerimiento HH Producción (3·(X_A+X_B)) | B43: =$B$23*(B27+B28) -> 0 | C43: =$B$23*(C27+C28) -> 0 | D43: =$B$23*(D27+D28) -> 0 | E43: =$B$23*(E27+E28) -> 0 | F43: =$B$23*(F27+F28) -> 0 | G43: =$B$23*(G27+G28) -> 0 | H43: =$B$23*(H27+H28) -> 0 | I43: =$B$23*(I27+I28) -> 0 | ... M43: =$B$23*(M27+M28) -> 0 | N43: —
A44: Horas Disponibles (W_t + O_t) | B44: =B40+B33 -> 300 | C44: =C40+C33 -> 300 | D44: =D40+D33 -> 300 | E44: =E40+E33 -> 300 | F44: =F40+F33 -> 300 | G44: =G40+G33 -> 300 | H44: =H40+H33 -> 300 | I44: =I40+I33 -> 300 | ... M44: =M40+M33 -> 300 | N44: —
A46: 4. FUNCIÓN OBJETIVO Y RESULTADOS FINANCIEROS
...

Sheet Comparación y Análisis
A1: COMPARACIÓN DE ESCENARIOS (se actualiza automáticamente tras correr Solver en ambas hojas)
A3: Métrica | B3: Parte 1 (Base sin RRHH) | C3: Parte 2 (Con RRHH)
A4: Ingresos Totales ($) | B4: ='Parte 1 - Modelo Base'!B35 -> 0 | C4: ='Parte 2 - Con RRHH'!B47 -> 0
A5: Costo Inventario ($) | B5: ='Parte 1 - Modelo Base'!B36 -> 760 | C5: ='Parte 2 - Con RRHH'!B48 -> 760
A6: Costo Mano de Obra Regular ($) | B6: =0 -> 0 | C6: ='Parte 2 - Con RRHH'!B49 -> 8100
A7: Costo Horas Extras ($) | B7: =0 -> 0 | C7: ='Parte 2 - Con RRHH'!B50 -> 0
A8: Costo Contratación ($) | B8: =0 -> 0 | C8: ='Parte 2 - Con RRHH'!B51 -> 0
A9: Costo Despido ($) | B9: =0 -> 0 | C9: ='Parte 2 - Con RRHH'!B52 -> 0
A10: BENEFICIO NETO ($) | B10: ='Parte 1 - Modelo Base'!B37 -> -760 | C10: ='Parte 2 - Con RRHH'!B53 -> -8860
A12: Diferencia (Parte 1 - Parte 2) ($) | B12: =B11-C11 -> 0
